Workbook

Sheet README
A1: Futures Prop Firm — Full-Lifecycle Statistics & Economics Model
A2: Monte-Carlo of the whole funnel (buy -> pass eval -> funded -> payout) + live firm P&L driven by rule design.
B4: WHAT CHANGED IN THIS VERSION
C5: The simulator now models BOTH phases with the SAME traders carried through:
C6: Evaluation rules : profit target, drawdown type/size, daily-loss limit, eval consistency, min trading days.
C7: Funded rules : funded drawdown type/size, funded consistency, min days to payout, winning-day count + floor,
C8: payout buffer / safety net, per-request payout cap, max payouts, profit split.
C9: Every one is a lever with its own sensitivity sweep. Firm Economics is now driven by rule design end-to-end.
B11: THE FOUR OUTPUTS THAT MATTER
C12: eval pass % -> how many buyers become funded (drives volume of funded liability).
C13: funded -> payout % -> of funded, how many ever draw cash (the real FPFX ~45% number).
C14: firm $ / funded -> average cash the FIRM pays out per funded trader over the account life (per $50K account).
C15: This single number = reached-rate x #payouts x payout size x split. It is your payout liability.
C16: net profit / margin-> what the firm keeps after payouts, marketing, processing and fixed costs.
B18: ORGANIZATION (18 tabs)
C19: DATA: Industry Data | Payout Reality Check | Firm Plans (Rules) - 16 firms, verified, incl. all-in price, cap, cadence, live path.
C20: MODEL: Firm Model (Economics) - every plan simulated | Eval + Funded sensitivity tabs | Our Firm - Plans (our floor-priced strategy).
C21: MONEY: Platform & Data Costs | Firm Economics | Cost Stack (full margin) | 18-Month Projection (treasury survival test).
C22: LEVERS: Pricing Power (discount floor).
C23: RISK: Risk Engine (VaR) - correlated payout tails + ruin by capital | Risk Operations - dashboard, abuse detection, monitoring stats.
C24: LAUNCH: Live Program (cost-reducer design) | Legal & Compliance | Launch Playbook.
B26: HOW TO USE
C27: 1. Firm Plans (Rules) = the verified competitive landscape. Our Firm - Plans = our answer, priced at the floor.
C28: 2. 18-Month Projection = the survival test (payout lag + correlated spike, not unit economics, kills firms).
C29: 3. Live Program: graduating winners to real capital CUTS cost — live terms can be unrestricted.
C30: 4. Re-run mc_lifecycle.py after any rule change; blue cells are editable everywhere.
B32: COLOR LEGEND
C33: BLUE = input / lever you set. BLACK = formula. GREEN = pulled from another tab. YELLOW = key assumption to review.
B35: CALIBRATION (trust the relative moves; treat absolutes as estimates)
C36: Trader skill distribution tuned so composites reproduce public aggregates:
C37: Eval pass: Topstep-style 15.3% (reported 16.8%) | Apex-style 14.6% (reported 15-20%) | TPT-style 22% (reported ~20%).
C38: Funnel: funded->payout ~55% modeled vs FPFX ~45% (FPFX includes forex; a futures-only book runs a bit higher).
C39: overall buyer-paid ~8% modeled vs ~7% reported. Average payout ~4% of nominal, matched.
C40: Real per-rule causal data is proprietary. Engine = mc_lifecycle.py; re-run with your own skill/rule assumptions.
B42: DISCLAIMER
C43: Planning model, not financial/legal/tax advice. US futures-prop regulation is unsettled (CFTC consultation closes 30 Nov 2026).
C44: Validate assumptions, payout-reserve adequacy, and legal/registration posture with qualified counsel before launch.

Sheet Industry Data
A1: Industry Data — Real, Sourced
A2: Self-reported by firms or third-party datasets; directional (no audited central database exists).
A4: Metric | B4: Value | C4: Source
A5: Evaluation pass rate (large independent set) | B5: 0.14 | C5: FPFX Technologies 300k+ accounts / 100k traders / 10 firms (Finance Magnates)
A6: Funded traders who ever reach a payout | B6: 0.45 | C6: FPFX Technologies dataset
A7: All challenge buyers who ever get paid | B7: 0.07 | C7: FPFX Technologies dataset
A8: Average payout (share of nominal account) | B8: 0.04 | C8: FPFX Technologies dataset
A9: Winner return on total fees spent | B9: 4 | C9: FPFX: $7.6M paid vs $1.9M invested
A10: Topstep — 2025 Combine completion rate | B10: 0.168 | C10: Topstep site disclosure, Jan-Dec 2025
A11: Take Profit Trader — 1-step pass rate | B11: 0.2037 | C11: TPT disclosure, Jan-Aug 2023
A12: Apex — first-attempt pass rate | B12: 0.175 | C12: Apex self-reported (15-20% midpoint)
A13: Share of Phase-1 failures = daily-drawdown breach | B13: 0.71 | C13: tradeclaris.com industry data
A14: Apex cumulative payouts since 2022 | B14: 439408133 | C14: Apex / quantvps.com 2026
A15: Industry payouts in 2025 | B15: 325000000 | C15: apextraderfunding.com
A16: Global prop market size (est.) | B16: 20000000000 | C16: 2026 industry summaries
... A22: Apex max payouts per PA (then converts) | B22: 6 | C22: Apex 4.0 rules 2026

Sheet Firm Plans (Rules)
A1: Firm Plans — Verified Rules, 16 Firms (Aug 2026)
A2: 50K tier canonical (25K where flagship). Verified vs firm help centers + PickAPropFirm live table (all-in incl. activation). Rules change constantly — re-verify before relying.
A4: Firm | B4: Plan | C4: Size | D4: Billing / all-in | E4: All-in $ | F4: Eval DD | G4: Eval cons. | H4: Ev min | I4: Funded DD | J4: Fund cons. | K4: 1st payout gate | L4: Pay gap | M4: Payout cap | N4: Split | O4: Max acc | P4: Live path / notes
A5: Apex | B5: Intraday | C5: 50K | D5: OTP, promo no-act. | E5: 79 | F5: Trail intraday | G5: None | H5: 0 | I5: Trail intraday | J5: 50% | K5: 5 qual. days $200+ | L5: 5d | M5: $1,500 | N5: 100% | O5: 20 | P5: Invitation-only Live; Bonus Vault 20-40%; daily, no rules on live
A6: Apex | B6: EOD | C6: 50K | D6: OTP, promo no-act. | E6: 119 | F6: Trail EOD | G6: None | H6: 0 | I6: Trail EOD | J6: 50% | K6: 5 qual. days $250+ | L6: 5d | M6: $1,500 | N6: 100% | O6: 20 | P6: 6-payout ladder then Live consideration
A7: Apex | B7: Intraday (non-promo) | C7: 50K | D7: OTP $25 + $79 act. | E7: 104 | F7: Trail intraday | G7: None | H7: 0 | I7: Trail intraday | J7: 50% | K7: 5 qual. days | L7: 5d | M7: $1,500 | N7: 100% | O7: 20 | P7: $99 PA activation when not promo-waived
A8: Apex | B8: Legacy | C8: 50K | D8: Sub $20/mo + $125 act. + $85/mo PA | E8: 145 | F8: Trailing | G8: None | H8: 1 | I8: Trailing | J8: 50% | K8: 8 days | L8: 8d | M8: $2,000 | N8: 100% | O8: 20 | P8: Old ruleset; PA monthly fee
A9: Topstep | B9: Combine -> Express | C9: 50K | D9: Sub $101/mo (+$149 act. on Standard) | E9: 201 | F9: Trail EOD (locks at start) | G9: 50% | H9: 2 | I9: Trail EOD | J9: None (Std) / 40% | K9: 5 win days $150+ | L9: 5d | M9: 50% bal, $2,000 | N9: 90/10 | O9: 5 | P9: Risk-team promotion to Live; MLL resets $0 post-payout
A10: TakeProfit Trader | B10: Test -> PRO | C10: 50K | D10: Sub $102/mo, $0 act. | E10: 102 | F10: Trail EOD | G10: 50% | H10: 5 | I10: Trail intraday (PRO) | J10: None | K10: Buffer zone: bal $52,000 | L10: 1d (daily) | M10: None above buffer (50% penalty below) | N10: 80/20 | O10: 5 | P10: PRO+ = LIVE acct: EOD DD, 90/10, no buffer; DLL $1,100; 4:10pm close
A11: MyFundedFutures | B11: Rapid | C11: 50K | D11: Sub $79/mo, $0 act. | E11: 79 | F11: Trail EOD | G11: 30% | H11: 2 | I11: Trail intraday (locks +$100) | J11: None | K11: $2,100 buffer | L11: 1d (daily) | M11: None ($500 min) | N11: 90/10 | O11: 5 | P11: Rapid Live at $10K/day profit or risk approval: $0-start, EOD, no buffer
A12: MyFundedFutures | B12: Rapid EOD (new) | C12: 50K | D12: OTP $126 | E12: 126 | F12: Trail EOD | G12: 30% | H12: 4 | I12: Trail EOD | J12: None | K12: $2,100 first buffer, then $500 net/cycle | L12: 1d (daily) | M12: None ($500 min) | N12: 90/10 | O12: 3 | P12: Stays EOD in funded — the differentiator
A13: MyFundedFutures | B13: Pro | C13: 50K | D13: Sub $114/mo, $0 act. | E13: 114 | F13: Trail EOD | G13: None | H13: 2 | I13: Trail EOD (locks start+$100 after 1st) | J13: None | K13: 14 calendar days; $2,100 buffer; $1,000 min | L13: 14d | M13: $100K lifetime; 60% one-time pre-buffer | N13: 80/20 | O13: 5 | P13: Bi-weekly cadence; no consistency anywhere in funded
A14: Tradeify | B14: Growth | C14: 50K | D14: OTP $87, $0 act. | E14: 87 | F14: Trail EOD | G14: None | H14: 1 | I14: Trail EOD | J14: 35% | K14: 5 qual. days $150+ | L14: 5d | M14: $1,500 | N14: 90/10 | O14: 5 | P14: —
A15: Tradeify | B15: Select Flex | C15: 50K | D15: OTP $99, $0 act. | E15: 99 | F15: Trail EOD | G15: 40% | H15: 3 | I15: Trail EOD | J15: None | K15: 5 win days | L15: 5d | M15: $3,000 | N15: 90/10 | O15: 5 | P15: —
A16: Tradeify | B16: Select Daily | C16: 50K | D16: OTP $99, $0 act. | E16: 99 | F16: Trail EOD | G16: 40% | H16: 3 | I16: Trail EOD | J16: None | K16: day 1 | L16: 1d (daily) | M16: $1,000 | N16: 90/10 | O16: 5 | P16: Daily variant trades cap for cadence
... A46: OUR FIRM | B46: Direct (D2F) | C46: 50K | D46: OTP ~$303 instant | E46: 303 | F46: — | G46: — | H46: — | I46: Trail EOD 4% | J46: 25% | K46: 5 win days; $1,500 buffer | L46: 5d | M46: $1,500 | N46: 90/10 | O46: 5 | P46: Instant; tightest funded rules
A48: All-in $ = discounted price + any activation (the true cost to reach funded). Billing shows the structure: OTP / subscription / +activation / D2F instant.
A49: Verified sources: firm help centers (helpfutures.fundednext.com, help.myfundedfutures.com, apextraderfunding.com, help.topstep.com), PickAPropFirm live table (re-synced 15-min, verified vs firm sites), tradecovex, damnpropfirms, proptradingvibes (Aug 2026). "—verify" (BluSky/Legends/Day Traders consistency) = not yet confirmed from a primary source; all E8/The5ers/Tradeify/FundedNext/MFF cells now verified from official help centers.
A50: Patterns: EOD trailing is now the default funded DD (MFF Rapid EOD, FundedNext, Tradeify, Lucid all market "stays EOD"). Daily cadence pairs with tight caps. $0 activation is standard except Apex/Topstep/Bulenox/Day Traders. Only Phidias offers overnight + direct-to-real-live.

Sheet Our Firm — Plans
A1: Our Firm — Recommended Competitive Plans
A2: Priced at the market floor, engineered to stay profitable via LOW firm $/funded (payout cap + funded consistency + cadence). Green = modeled. Blue = editable. Black = formula.
A4: Shared cost inputs (edit): | B4: Affiliate % of price | C4: 0.15
B5: Fixed ads / buyer ($) | C5: 8
B6: Serve / buyer ($, from Platform tab logic) | C6: 34
A8: Metric | B8: Core EOD (eval) | C8: Rapid Daily (eval) | D8: Direct (instant)
A9: PRICING & MARKET POSITION
A10: List price 50K ($) | B10: 99 | C10: 110 | D10: 379
A11: Typical discount | B11: 0.2 | C11: 0.2 | D11: 0.2
A12: Effective (floor) price 50K ($) | B12: 79 | C12: 88 | D12: 303
A13: Structure | B13: Eval, no activation | C13: Eval, no activation | D13: Instant funding
A14: Market floor at 50K (reference) | B14: $59-90 (TradeDay/Apex/MFF/Lucid) | C14: $79-114 (MFF/TradeDay Rapid/daily) | D14: $295-364 (Lightning/Direct D2F)
A15: OUR RULES — EVALUATION
A16: Eval drawdown | B16: Trail EOD 5% | C16: Trail EOD 5% | D16: - (instant)
A17: Eval profit target | B17: 6% ($3,000) | C17: 6% ($3,000) | D17: -
A18: Eval consistency | B18: None | C18: 30% | D18: -
A19: Eval min days | B19: 1 | C19: 2 | D19: -
A20: OUR RULES — FUNDED (the liability controls)
A21: Funded drawdown | B21: Trail EOD 5% | C21: Trail EOD 5% | D21: Trail EOD 5%
A22: Funded consistency | B22: 30% | C22: 40% | D22: 25%
A23: Min days to first payout | B23: day 1 | C23: 5 | D23: 5
A24: Winning days + $/day (50K) | B24: 5 days, $150 | C24: 5 days, $150 | D24: 5 days, $150
A25: Payout buffer (50K) | B25: $1,000 | C25: $1,000 | D25: $1,500
A26: Payout cap per request (50K) | B26: $1,500 | C26: $1,000 | D26: $1,500
A27: Pay gap (days between payouts) | B27: 5 | C27: 1 (daily) | D27: 5
A28: Payout processing | B28: INSTANT auto-approval; settles 2-3 biz days via Rise | C28: INSTANT auto-approval; settles 2-3 biz days via Rise | D28: INSTANT auto-approval; settles 2-3 biz days via Rise
A29: Profit split | B29: 90/9 | C29: 90/9 | D29: 90/9
A30: Max funded accounts | B30: 10 | C30: 5 | D30: 5
A31: MODELED OUTCOMES (Monte Carlo)
A32: Eval pass rate | B32: 0.26538 | C32: 0.16622 | D32: 1
A33: Funded -> payout rate | B33: 0.33958851 | C33: 0.46697148 | D33: 0.12046
A34: Firm $/funded (50K) | B34: 698 | C34: 800 | D34: 206
A35: PER-BUYER ECONOMICS (live)
A36: Revenue / buyer | B36: =B12*3+B31*0 -> 237 | C36: =C12*2.8+C31*0 -> 246.4 | D36: =D12*1.6 -> 484.8
A37: Payout liability / buyer | B37: =B32*B34 -> 185.23524 | C37: =C32*C34 -> 132.976 | D37: =D34 -> 206
A38: Affiliate CAC + ads | B38: =$C$4*B12+$C$5 -> 19.85 | C38: =$C$4*C12+$C$5 -> 21.2 | D38: =$C$4*D12+$C$5 -> 53.45
A39: Cost to serve | B39: =$C$6 -> 34 | C39: =$C$6 -> 34 | D39: =$C$6 -> 34
A40: CONTRIBUTION / buyer | B40: =B36-B37-B38-B39 -> -2.08524 | C40: =C36-C37-C38-C39 -> 58.224 | D40: =D36-D37-D38-D39 -> 191.35
A41: Contribution margin | B41: =IF(B36=0,0,B40/B36) -> -0.008798481 | C41: =IF(C36=0,0,C40/C36) -> 0.2362987 | D41: =IF(D36=0,0,D40/D36) -> 0.39469884
A43: DESIGN LOGIC: attractive, loose EVALUATION (low/no eval consistency, EOD drawdown, low min days) to WIN customers on rules + price — then keep the FUNDED phase liability low (payout cap + funded consistency + a sensible pay gap) so firm $/funded stays ~$200-850 instead of $2,000-5,000.
...

Sheet Firm Model (Economics)
A1: Firm Model — Every Plan Run Through the Model
A2: Each real plan simulated end-to-end, then costed per buyer. Shows how each firm stays solvent. Green = modeled (Monte Carlo). Black = live formula. Blue = shared cost inputs.
A4: Shared cost inputs (edit): | C4: Affiliate % of price | D4: 0.15 | E4: Serve / buyer ($) | F4: 34 | G4: Fixed ads / buyer ($) | H4: 8 | I4: Funded trade-through | J4: 1
A6: Firm | B6: Plan | C6: Structure | D6: Eff. price | E6: Eval pass | F6: Funded->pay | G6: Firm $/funded | H6: Revenue/buyer | I6: Liab./buyer | J6: Contrib./buyer | K6: Margin
A7: Apex | B7: Intraday | C7: Eval+Activation | D7: 59 | E7: 0.14648 | F7: 0.47747133 | G7: 2049 | H7: =D7*4+E7*79 -> 247.57192 | I7: =E7*G7*$J$4 -> 300.13752 | J7: =H7-I7-($D$4*D7+$H$4)-$F$4 -> -103.4156 | K7: =IF(H7=0,0,J7/H7) -> -0.41771942
A8: Apex | B8: EOD | C8: Eval+Activation | D8: 89 | E8: 0.16654 | F8: 0.48516873 | G8: 2062 | H8: =D8*4+E8*99 -> 372.48746 | I8: =E8*G8*$J$4 -> 343.40548 | J8: =H8-I8-($D$4*D8+$H$4)-$F$4 -> -26.26802 | K8: =IF(H8=0,0,J8/H8) -> -0.070520549
A9: Topstep | B9: Standard | C9: Subscription | D9: 91 | E9: 0.1174 | F9: 0.49454855 | G9: 2111 | H9: =D9*3.2+E9*0 -> 291.2 | I9: =E9*G9*$J$4 -> 247.8314 | J9: =H9-I9-($D$4*D9+$H$4)-$F$4 -> -12.2814 | K9: =IF(H9=0,0,J9/H9) -> -0.042175137
A10: Topstep | B10: Consistency | C10: Subscription | D10: 91 | E10: 0.1189 | F10: 0.43885618 | G10: 2872 | H10: =D10*3.2+E10*0 -> 291.2 | I10: =E10*G10*$J$4 -> 341.4808 | J10: =H10-I10-($D$4*D10+$H$4)-$F$4 -> -105.9308 | K10: =IF(H10=0,0,J10/H10) -> -0.36377335
A11: Take Profit Trader | B11: PRO | C11: Eval, no activation | D11: 98 | E11: 0.1509 | F11: 0.42862823 | G11: 3799 | H11: =D11*3+E11*0 -> 294 | I11: =E11*G11*$J$4 -> 573.2691 | J11: =H11-I11-($D$4*D11+$H$4)-$F$4 -> -335.9691 | K11: =IF(H11=0,0,J11/H11) -> -1.142752
A12: MyFundedFutures | B12: Expert | C12: Eval, no activation | D12: 98 | E12: 0.12442 | F12: 0.46969941 | G12: 2357 | H12: =D12*3+E12*0 -> 294 | I12: =E12*G12*$J$4 -> 293.25794 | J12: =H12-I12-($D$4*D12+$H$4)-$F$4 -> -55.95794 | K12: =IF(H12=0,0,J12/H12) -> -0.19033313
A13: MyFundedFutures | B13: Flex | C13: Eval, no activation | D13: 75 | E13: 0.47698 | F13: 0.37913539 | G13: 1303 | H13: =D13*3.2+E13*0 -> 240 | I13: =E13*G13*$J$4 -> 621.50494 | J13: =H13-I13-($D$4*D13+$H$4)-$F$4 -> -434.75494 | K13: =IF(H13=0,0,J13/H13) -> -1.8114789
A14: Tradeify | B14: Growth | C14: Eval, no activation | D14: 80 | E14: 0.16644 | F14: 0.35988945 | G14: 1046 | H14: =D14*3.2+E14*0 -> 256 | I14: =E14*G14*$J$4 -> 174.09624 | J14: =H14-I14-($D$4*D14+$H$4)-$F$4 -> 27.90376 | K14: =IF(H14=0,0,J14/H14) -> 0.10899906
A15: Tradeify | B15: Select | C15: Eval, no activation | D15: 91 | E15: 0.14152 | F15: 0.48134539 | G15: 2402 | H15: =D15*3+E15*0 -> 273 | I15: =E15*G15*$J$4 -> 339.93104 | J15: =H15-I15-($D$4*D15+$H$4)-$F$4 -> -122.58104 | K15: =IF(H15=0,0,J15/H15) -> -0.4490148
A16: Tradeify | B16: Lightning | C16: Instant funding | D16: 418 | E16: 1 | F16: 0.12062 | G16: 278 | H16: =D16*1.6+1*0 -> 668.8 | I16: =1*G16*$J$4 -> 278 | J16: =H16-I16-($D$4*D16+$H$4)-$F$4 -> 286.1 | K16: =IF(H16=0,0,J16/H16) -> 0.4277811
A17: TradeDay | B17: Quick Pay | C17: Subscription | D17: 68 | E17: 0.09384 | F17: 0.7685422 | G17: 1255 | H17: =D17*3.2+E17*0 -> 217.6 | I17: =E17*G17*$J$4 -> 117.7692 | J17: =H17-I17-($D$4*D17+$H$4)-$F$4 -> 47.6308 | K17: =IF(H17=0,0,J17/H17) -> 0.21889154
A18: TradeDay | B18: Fast Pass | C18: Subscription | D18: 68 | E18: 0.15318 | F18: 0.48374461 | G18: 2412 | H18: =D18*3+E18*0 -> 204 | I18: =E18*G18*$J$4 -> 369.47016 | J18: =H18-I18-($D$4*D18+$H$4)-$F$4 -> -217.67016 | K18: =IF(H18=0,0,J18/H18) -> -1.0670106
A19: TopOne | B19: Elite Challenge | C19: Subscription | D19: 120 | E19: 0.26756 | F19: 0.27889072 | G19: 826 | H19: =D19*3+E19*0 -> 360 | I19: =E19*G19*$J$4 -> 221.00456 | J19: =H19-I19-($D$4*D19+$H$4)-$F$4 -> 78.99544 | K19: =IF(H19=0,0,J19/H19) -> 0.21943178
A20: TopOne | B20: S2F PRO | C20: Instant funding | D20: 412 | E20: 1 | F20: 0.17958 | G20: 476 | H20: =D20*1.6+1*0 -> 659.2 | I20: =1*G20*$J$4 -> 476 | J20: =H20-I20-($D$4*D20+$H$4)-$F$4 -> 79.4 | K20: =IF(H20=0,0,J20/H20) -> 0.12044903
A21: Lucid Trading | B21: LucidPro | C21: Eval, no activation | D21: 90 | E21: 0.26428 | F21: 0.39874376 | G21: 1245 | H21: =D21*3+E21*0 -> 270 | I21: =E21*G21*$J$4 -> 329.0286 | J21: =H21-I21-($D$4*D21+$H$4)-$F$4 -> -114.5286 | K21: =IF(H21=0,0,J21/H21) -> -0.42418
A22: Lucid Trading | B22: LucidFlex | C22: Eval, no activation | D22: 112 | E22: 0.23952 | F22: 0.49398798 | G22: 2153 | H22: =D22*2.8+E22*0 -> 313.6 | I22: =E22*G22*$J$4 -> 515.68656 | J22: =H22-I22-($D$4*D22+$H$4)-$F$4 -> -260.88656 | K22: =IF(H22=0,0,J22/H22) -> -0.83190867
A23: Lucid Trading | B23: LucidDirect | C23: Instant funding | D23: 328 | E23: 1 | F23: 0.09366 | G23: 167 | H23: =D23*1.6+1*0 -> 524.8 | I23: =1*G23*$J$4 -> 167 | J23: =H23-I23-($D$4*D23+$H$4)-$F$4 -> 266.6 | K23: =IF(H23=0,0,J23/H23) -> 0.50800305
A24: MyFundedFutures | B24: Rapid EOD | C24: Eval, no activation | D24: 101 | E24: 0.11002 | F24: 0.52899473 | G24: 2379 | H24: =D24*2.2+E24*0 -> 222.2 | I24: =E24*G24*$J$4 -> 261.73758 | J24: =H24-I24-($D$4*D24+$H$4)-$F$4 -> -96.68758 | K24: =IF(H24=0,0,J24/H24) -> -0.43513762
A25: FundedNext | B25: Rapid Daily | C25: Eval, no activation | D25: 75 | E25: 0.12566 | F25: 0.5457584 | G25: 2089 | H25: =D25*2+E25*0 -> 150 | I25: =E25*G25*$J$4 -> 262.50374 | J25: =H25-I25-($D$4*D25+$H$4)-$F$4 -> -165.75374 | K25: =IF(H25=0,0,J25/H25) -> -1.1050249
A26: Bulenox | B26: Option 1 | C26: Sub + activation | D26: 167 | E26: 0.23346 | F26: 0.37419686 | G26: 872 | H26: =D26*2.5+E26*0 -> 417.5 | I26: =E26*G26*$J$4 -> 203.57712 | J26: =H26-I26-($D$4*D26+$H$4)-$F$4 -> 146.87288 | K26: =IF(H26=0,0,J26/H26) -> 0.35179133
A27: The5ers | B27: Day Trade | C27: Eval, no activation | D27: 64 | E27: 0.1648 | F27: 0.58968447 | G27: 859 | H27: =D27*2.2+E27*0 -> 140.8 | I27: =E27*G27*$J$4 -> 141.5632 | J27: =H27-I27-($D$4*D27+$H$4)-$F$4 -> -52.3632 | K27: =IF(H27=0,0,J27/H27) -> -0.37189773
A28: E8 Futures | B28: Zero Starter | C28: Eval, no activation | D28: 116 | E28: 0.07758 | F28: 0.26218097 | G28: 346 | H28: =D28*2.3+E28*0 -> 266.8 | I28: =E28*G28*$J$4 -> 26.84268 | J28: =H28-I28-($D$4*D28+$H$4)-$F$4 -> 180.55732 | K28: =IF(H28=0,0,J28/H28) -> 0.67675157
A29: BluSky | B29: Propel | C29: Subscription | D29: 112 | E29: 0.16514 | F29: 0.3337774 | G29: 1339 | H29: =D29*2.8+E29*0 -> 313.6 | I29: =E29*G29*$J$4 -> 221.12246 | J29: =H29-I29-($D$4*D29+$H$4)-$F$4 -> 33.67754 | K29: =IF(H29=0,0,J29/H29) -> 0.10739011
A30: Legends Trading | B30: Elite | C30: Eval, no activation | D30: 121 | E30: 0.20532 | F30: 0.32593026 | G30: 886 | H30: =D30*2+E30*0 -> 242 | I30: =E30*G30*$J$4 -> 181.91352 | J30: =H30-I30-($D$4*D30+$H$4)-$F$4 -> -0.06352 | K30: =IF(H30=0,0,J30/H30) -> -0.00026247934
A31: Phidias | B31: Fundamental | C31: Eval, no activation | D31: 116 | E31: 0.17858 | F31: 0.36935827 | G31: 848 | H31: =D31*2+E31*0 -> 232 | I31: =E31*G31*$J$4 -> 151.43584 | J31: =H31-I31-($D$4*D31+$H$4)-$F$4 -> 21.16416 | K31: =IF(H31=0,0,J31/H31) -> 0.091224828
A32: Day Traders | B32: Static | C32: Eval + activation | D32: 20 | E32: 0.36354 | F32: 0.30175497 | G32: 840 | H32: =D32*2.5+E32*99 -> 85.99046 | I32: =E32*G32*$J$4 -> 305.3736 | J32: =H32-I32-($D$4*D32+$H$4)-$F$4 -> -264.38314 | K32: =IF(H32=0,0,J32/H32) -> -3.0745636
A33: OUR FIRM | B33: Core EOD (eval) | C33: Eval, no activation | D33: 79 | E33: 0.26538 | F33: 0.33958851 | G33: 698 | H33: =D33*3+E33*0 -> 237 | I33: =E33*G33*$J$4 -> 185.23524 | J33: =H33-I33-($D$4*D33+$H$4)-$F$4 -> -2.08524 | K33: =IF(H33=0,0,J33/H33) -> -0.008798481
A34: OUR FIRM | B34: Rapid Daily (eval) | C34: Eval, no activation | D34: 88 | E34: 0.16622 | F34: 0.46697148 | G34: 800 | H34: =D34*2.8+E34*0 -> 246.4 | I34: =E34*G34*$J$4 -> 132.976 | J34: =H34-I34-($D$4*D34+$H$4)-$F$4 -> 58.224 | K34: =IF(H34=0,0,J34/H34) -> 0.2362987
A35: OUR FIRM | B35: Direct (instant) | C35: Instant funding | D35: 303 | E35: 1 | F35: 0.12046 | G35: 206 | H35: =D35*1.6+1*0 -> 484.8 | I35: =1*G35*$J$4 -> 206 | J35: =H35-I35-($D$4*D35+$H$4)-$F$4 -> 191.35 | K35: =IF(H35=0,0,J35/H35) -> 0.39469884
A37: Eff. price (blue) = list x typical blended discount (not the 90%-off holiday floor — that is a minority of buyers). Override to test any promo. Revenue/buyer = eff price x lifetime purchases + activation (passers only).
A38: Liability/buyer = funded rate x firm $/funded. For instant plans funded rate = 100%, so the FULL firm $/funded hits every buyer — which is why instant plans run the tightest funded rules (lowest firm $/funded).
A39: THE SIGNAL IS THE firm $/funded COLUMN. It ranges ~$350 (Tradeify Lightning, tight instant) to ~$5,200 (LucidFlex, uncapped) — a 15x spread set entirely by funded-rule design (caps, consistency, buffer, split).
A40: ENGINE v2 realism corrections: (1) 10% payout-denial rate (rule violations at request time); (2) post-payout risk-up x1.5 (house-money effect kills accounts faster after extraction — matches real post-payout floors); (3) 85% funded trade-through (passers who never activate). Together these pull uncapped-plan liability toward the real FPFX anchor (~$4k gross per payer).
A41: Real firms turn thin per-buyer economics into profit through VOLUME (millions of accounts), REBUYS (short eval windows), ACTIVATION fees (Apex), and ACCOUNT STACKING (Apex 20). This tab isolates one buyer; the Firm Economics tab scales it.
A42: Modeled pass / funded->pay / firm $/funded are Monte-Carlo estimates calibrated to public aggregates (eval ~15%, funded->pay ~48%, overall ~7%). Treat absolutes as directional; the RELATIVE spread between plans is the signal.

Sheet Payout Reality Check
A1: Payout Reality Check — Real On-Chain Data (7 days)
A2: Blockchain-verified futures-firm payouts from payoutjunction.com/7d (Aug 11 2026). On-chain only = a FLOOR; firms also pay via bank/other. Validates the model.
A4: Firm (futures) | B4: 7-day payouts | C4: Count | D4: Avg payout | E4: Largest | F4: Annualized (x52, floor)
A5: Tradeify | B5: 9963425 | C5: 5819 | D5: 1712 | E5: 28118 | F5: =B5*52 -> 518098100
A6: MyFundedFutures | B6: 3227507 | C6: 2019 | D6: 1599 | E6: 109654 | F6: =B6*52 -> 167830364
A7: FundedFuturesFamily | B7: 629744 | C7: 413 | D7: 1525 | E7: 7269 | F7: =B7*52 -> 32746688
A8: FuturesElite | B8: 473458 | C8: 220 | D8: 2152 | E8: 37765 | F8: =B8*52 -> 24619816
A9: TopOneFutures | B9: 219935 | C9: 154 | D9: 1428 | E9: 8000 | F9: =B9*52 -> 11436620
A10: GoatFundedFutures | B10: 206565 | C10: 145 | D10: 1425 | E10: 5000 | F10: =B10*52 -> 10741380
A11: TradeDay | B11: 172296 | C11: 163 | D11: 1057 | E11: 2703 | F11: =B11*52 -> 8959392
A12: AlphaFutures | B12: 71758 | C12: 34 | D12: 2111 | E12: 16699 | F12: =B12*52 -> 3731416
A13: TopOneTrader | B13: 43675 | C13: 33 | D13: 1323 | E13: 10094 | F13: =B13*52 -> 2271100
A14: Elite Trader Funding | B14: 39542 | C14: 47 | D14: 841 | E14: 2500 | F14: =B14*52 -> 2056184
A15: AquaFutures | B15: 20746 | C15: 10 | D15: 2075 | E15: 7000 | F15: =B15*52 -> 1078792
A16: TOTAL / blended | B16: =SUM(B5:B15) -> 15068651 | C16: =SUM(C5:C15) -> 9057 | D16: =B16/C16 -> 1663.7574 | F16: =B16*52 -> 783569852
A18: Blended average payout across these futures firms computes in D16 — it lands around $1,600, squarely inside the model's ~$1,700/payout (50K) assumption. The model is calibrated to reality.
A19: The tail is real: MyFundedFutures shows a single $109,654 payout and Tradeify a $28,118 one in a single week — exactly the correlated/large-winner spike the reserve model sizes for.
A20: Tradeify moved ~$10M in 7 days on-chain alone (a floor). Payout volume of this scale is only survivable when fee revenue from the ~85% who fail dwarfs it — which is the whole business model.
A21: CAVEAT: on-chain (Rise/crypto) captures only part of total payouts, and some wallet flows may be operational, not trader payouts. Treat counts and AVERAGES as the reliable signal; totals as directional floors.
A22: Source: payoutjunction.com/7d, blockchain-verified, retrieved Aug 11 2026. Apex (not on this tracker) separately reports ~$15.4M/mo avg payouts, $598M since 2022 (quantvps).

Sheet Eval Pass-Rate Model
A1: Evaluation Pass-Rate Model — Monte Carlo (MODELED)
A2: 60,000 simulated traders per row. Failure columns = share of the whole population. Estimates, not guarantees.
A4: BASELINE eval (5% EOD-trail, 2% daily loss, 50% consistency, 6% target, 2 min days)
A5: Scenario | B5: Pass rate | C5: Fail:DailyLoss | D5: Fail:MaxDD | E5: Fail:Consistency | F5: Fail:Time
A6: Baseline | B6: 0.1516 | C6: 0.65081667 | D6: 0.18461667 | E6: 0.00018333333 | F6: 0.012783333
A7: ~70% of the population fails on the daily-loss limit — matches the real ~71% Phase-1 stat.
A9: DRAWDOWN TYPE (size held 5%)
A10: Scenario | B10: Pass rate | C10: Fail:DailyLoss | D10: Fail:MaxDD | E10: Fail:Consistency | F10: Fail:Time
A11: Static | B11: 0.21363333 | C11: 0.75196667 | D11: 0.0165 | E11: 0.00125 | F11: 0.01665
A12: Trailing (EOD) | B12: 0.15333333 | C12: 0.64903333 | D12: 0.18508333 | E12: 0.00025 | F12: 0.0123
A13: Trailing (intraday) | B13: 0.14156667 | C13: 0.62638333 | D13: 0.22048333 | E13: 0.00028333333 | F13: 0.011283333
A14: Static is most passable and shifts failures off drawdown onto the daily-loss limit.
A16: MAX DRAWDOWN SIZE
A17: Scenario | B17: Pass rate | C17: Fail:DailyLoss | D17: Fail:MaxDD | E17: Fail:Consistency | F17: Fail:Time
A18: 3% | B18: 0.0677 | C18: 0.53148333 | D18: 0.39598333 | E18: 0 | F18: 0.0048333333
A19: 5% | B19: 0.15116667 | C19: 0.65233333 | D19: 0.18381667 | E19: 0.00013333333 | F19: 0.01255
A20: 8% | B20: 0.19431667 | C20: 0.71715 | D20: 0.0677 | E20: 0.00088333333 | F20: 0.01995
A21: 10% | B21: 0.20191667 | C21: 0.73581667 | D21: 0.039466667 | E21: 0.0014 | F21: 0.0214
A23: DAILY LOSS LIMIT
A24: Scenario | B24: Pass rate | C24: Fail:DailyLoss | D24: Fail:MaxDD | E24: Fail:Consistency | F24: Fail:Time
A25: None | B25: 0.23791667 | C25: 0 | D25: 0.7444 | E25: 0.00033333333 | F25: 0.01735
A26: 2% | B26: 0.15313333 | C26: 0.65221667 | D26: 0.18185 | E26: 0.00021666667 | F26: 0.012583333
A27: 3% | B27: 0.21121667 | C27: 0.47178333 | D27: 0.30048333 | E27: 0.00043333333 | F27: 0.016083333
A28: 5% | B28: 0.23985 | C28: 0.22728333 | D28: 0.51468333 | E28: 0.00031666667 | F28: 0.017866667
A29: The single biggest eval pass-rate lever.
A31: CONSISTENCY (eval)
A32: Scenario | B32: Pass rate | C32: Fail:DailyLoss | D32: Fail:MaxDD | E32: Fail:Consistency | F32: Fail:Time
A33: None | B33: 0.17553333 | C33: 0.6337 | D33: 0.17898333 | E33: 0 | F33: 0.011783333
A34: 50% | B34: 0.15333333 | C34: 0.65045 | D34: 0.18368333 | E34: 0.00023333333 | F34: 0.0123
A35: 40% | B35: 0.12956667 | C35: 0.67018333 | D35: 0.18753333 | E35: 0.00073333333 | F35: 0.011983333
A36: 30% | B36: 0.09515 | C36: 0.6991 | D36: 0.19183333 | E36: 0.0011833333 | F36: 0.012733333
A37: 20% | B37: 0.0529 | C37: 0.72861667 | D37: 0.20121667 | E37: 0.0039166667 | F37: 0.01335
A39: MIN TRADING DAYS (eval)
A40: Scenario | B40: Pass rate | C40: Fail:DailyLoss | D40: Fail:MaxDD | E40: Fail:Consistency | F40: Fail:Time
A41: 0 days | B41: 0.15246667 | C41: 0.65001667 | D41: 0.18501667 | E41: 0.00023333333 | F41: 0.012266667
A42: 1 days | B42: 0.1512 | C42: 0.65383333 | D42: 0.1832 | E42: 0.00023333333 | F42: 0.011533333
A43: 2 days | B43: 0.15103333 | C43: 0.65151667 | D43: 0.18511667 | E43: 0.00018333333 | F43: 0.01215
A44: 5 days | B44: 0.12933333 | C44: 0.66903333 | D44: 0.1896 | E44: 0.00015 | F44: 0.011883333
A45: 10 days | B45: 0.083483333 | C45: 0.70536667 | D45: 0.19805 | E45: 0.0003 | F45: 0.0128
A46: Higher minimums cut pass rate by forcing more exposure days before a trader can lock the target.
...

Sheet Funded-Phase Model
A1: Funded-Phase Model — Monte Carlo (MODELED)
A2: Of eval-passers, who ever draws cash and how much. "Firm $/funded" (per $50K acct) = your payout liability per funded trader.
A4: BASELINE funded (5% EOD-trail, 50% consistency, 5 min days, 5 winning days $150+, DD+$100 buffer, $2k cap, 6 payouts, 90/10)
A5: Scenario | B5: Funded->payout | C5: Avg payouts/payer | D5: Avg payout $/50K | E5: Firm $/funded (50K)
A6: Baseline | B6: 0.48153034 | C6: 2.2175799 | D6: 1881.5183 | E6: 1808.231
A7: Firm $/funded is the key economic number — reached-rate x #payouts x payout size x split, all in one.
A9: FUNDED DRAWDOWN TYPE
A10: Scenario | B10: Funded->payout | C10: Avg payouts/payer | D10: Avg payout $/50K | E10: Firm $/funded (50K)
A11: Static | B11: 0.6592625 | C11: 2.3910373 | D11: 1909.5851 | E11: 2709.1076
A12: Trailing (EOD) | B12: 0.49283291 | C12: 2.2042629 | D12: 1877.9505 | E12: 1836.0722
A13: Trailing (intraday) | B13: 0.45376956 | C13: 2.2160598 | D13: 1876.553 | E13: 1698.3225
A14: Intraday trailing in funded is harshest (why TPT PRO accounts blow up in week 1). Static leaks the most cash.
A16: FUNDED DRAWDOWN SIZE
A17: Scenario | B17: Funded->payout | C17: Avg payouts/payer | D17: Avg payout $/50K | E17: Firm $/funded (50K)
A18: 3% | B18: 0.31130321 | C18: 2.1086116 | D18: 1849.3045 | E18: 1092.5243
A19: 5% | B19: 0.48615822 | C19: 2.2374522 | D19: 1888.622 | E19: 1848.9235
A20: 8% | B20: 0.60225408 | C20: 2.3010538 | D20: 1899.8379 | E20: 2369.5483
A21: 10% | B21: 0.64131743 | C21: 2.3371438 | D21: 1901.8672 | E21: 2565.5541
A22: Tighter funded DD cuts BOTH payout rate and firm liability sharply.
A24: FUNDED CONSISTENCY RULE
A25: Scenario | B25: Funded->payout | C25: Avg payouts/payer | D25: Avg payout $/50K | E25: Firm $/funded (50K)
A26: None | B26: 0.52106357 | C26: 2.7305754 | D26: 1820.1949 | E26: 2330.8015
A27: 50% | B27: 0.48200022 | C27: 2.2410897 | D27: 1881.0459 | E27: 1828.7249
A28: 40% | B28: 0.45748988 | C28: 1.9382923 | D28: 1910.8087 | E28: 1524.9671
A29: 30% | B29: 0.38078564 | C29: 1.5597701 | D29: 1942.4919 | E29: 1038.3479
A30: 20% | B30: 0.22212496 | C30: 1.1931034 | D30: 1979.7176 | E30: 472.19481
A31: A major liability throttle: 20% consistency roughly halves reached-rate AND cuts firm $/funded by ~70% vs none.
A33: MIN TRADING DAYS -> PAYOUT
A34: Scenario | B34: Funded->payout | C34: Avg payouts/payer | D34: Avg payout $/50K | E34: Firm $/funded (50K)
A35: 0 days | B35: 0.48375096 | C35: 2.2393124 | D35: 1880.3049 | E35: 1833.1892
A36: 3 days | B36: 0.48473575 | C36: 2.2266366 | D36: 1880.7434 | E36: 1826.9491
A37: 5 days | B37: 0.49600613 | C37: 2.2137657 | D37: 1876.7531 | E37: 1854.6773
A38: 8 days | B38: 0.46985447 | C38: 2.191197 | D38: 1898.8376 | E38: 1759.4427
A39: 10 days | B39: 0.46679068 | C39: 2.117909 | D39: 1919.9656 | E39: 1708.3051
A40: Barely moves reached-rate — a weak lever on its own. Mostly delays, not prevents, payouts.
A42: WINNING-DAY REQUIREMENT
A43: Scenario | B43: Funded->payout | C43: Avg payouts/payer | D43: Avg payout $/50K | E43: Firm $/funded (50K)
A44: 0 win-days | B44: 0.49195754 | C44: 2.3941281 | D44: 1827.5425 | E44: 1937.2471
A45: 3 win-days | B45: 0.50596345 | C45: 2.3994377 | D45: 1842.2292 | E45: 2012.8657
A46: 5 win-days | B46: 0.48320385 | C46: 2.2443388 | D46: 1882.2038 | E46: 1837.0795
...

Sheet Platform & Data Costs
A1: Platform, Data & Routing Costs (2026)
A2: The real infra stack: a fixed white-label PLATFORM licence + PER-ACCOUNT routing & data. Firms pay these on every live account (eval + funded).
A4: PROVIDER REFERENCE (2026, sourced)
A5: Provider / item | B5: Cost | C5: Notes & source
A6: -- WHITE-LABEL PLATFORM (fixed firm cost) --
A7: Whitelabel — upfront (insider) | B7: $30-40k setup | C7: Ex-FTT risk/tech insider (Jul 2025): whitelabel launch cost. At SCALE a top firm pays ~$150k/MO whitelabel — per-account fees compound. Apex's vendor reportedly made ~$70M.
A8: Own tech build (insider) | B8: ~$200k | C8: Same source: custom dashboard/risk/reset stack ~$200k (claims 4-8 wk build). Firms that OWN tech (FuturesElite, MFFU) are picked as long-term winners; whitelabel dependency helped kill Thrive.
A9: -- DXTRADE XT QUOTE (ACTUAL, Aug 2026, sheet MKT-1204) --
A10: DXtrade XT — setup | B10: $12,000 one-time | C10: Charged in advance. Includes branded web+mobile UIs, full sim, risk/ops portal, auto-liquidation, CRM integration.
A11: DXtrade XT — platform | B11: $2,400/mo min (200 accts) + $12/addl | C11: Monthly fee paid in advance; additional accounts billed at month end.
A12: dxFeed integration | B12: $2,400/mo min (200 users) + $12/addl | C12: Separate line from the platform minimum — the real floor is $4,800/mo + AWS.
A13: DXtrade market data (per user/mo) | B13: L1 CME $1.86 / L1 all-4 $5.58 | C13: L2 (depth/DOM): CME $14.52, all-4 $43.80. Futures traders expect the DOM -> realistic tier is L2 CME.
A14: AWS hosting | B14: pass-through | C14: Invoiced to the firm at month end — budget $500-2,000/mo, get an estimate in writing.
A15: CHARGEABLE-USER TRAP | B15: active status, not logins | C15: Any client in ACTIVE status at any point in the month bills — regardless of logins or trading. Worse than Rithmic (logs-in-that-month). Auto-EXPIRE/terminate churned accounts or pay for zombies.
A16: Per-user comparison (marginal) | B16: DXtrade ~$38.50 vs Rithmic ~$48 | C16: DXtrade L2 CME: $12+$12+$14.52 = $38.52. Rithmic CME-depth: $30+$18 = $48 ($40 with top-of-book only). DXtrade cheaper per user; Rithmic cheaper at SMALL scale (no $4,800 floor + $12k setup) and brings the ecosystem (NinjaTrader/Quantower/R|Trader + API) traders already use.
A17: Crossover math | B17: ~250-300 active accts | C17: Below ~250 actives: Rithmic-native wins (pay-per-user, no setup, trader-preferred platforms). Above ~300: DXtrade wins on raw cost. Decision: launch Rithmic-native, revisit DXtrade at scale or negotiate the floor/setup down now (it is a limited-time offer = negotiable).
A18: ProjectX (Sims2Funded) | B18: firm licence | C18: Browser white-label front-end on Rithmic; bundles costs so firms keep eval prices low. (fortraders, proptradingvibes 2026)
A19: PropForge / Tradovate Prop / FPFX | B19: flat/mo + per-acct | C19: Turnkey prop-tech; flat monthly plus per-account. In-house build = $1M+/12-18mo. (earlier research)
A20: -- RITHMIC TPAP QUOTE (ACTUAL, Aug 11 2026, Merit Futures) --
A21: Rithmic software licence | B21: $30/user/mo | C21: Per Trader User ID that LOGS IN that month (inactive = $0). Admin IDs waived. (Rithmic Support quote)
A22: Rithmic — API / unapproved platform | B22: $100/user/mo | C22: If user logs in via R|API composite or unapproved 3rd-party software that month. Algo traders cost 3.3x — charge them accordingly.
A23: Volume discount ladder | B23: 10-40% off | C23: After >$100k fees in 4 consecutive months: 10% ($100-300k), 20% ($300-750k), 30% ($750k-1.5M), 40% (>$1.5M). 60k users -> effective <$23/user.
A24: Private Order Plant | B24: $2,500/mo | C24: Only billed in months where software fees < $100k.
A25: CME data — non-pro TOP OF BOOK | B25: $10/user/mo FLAT | C25: All CME Group exchanges included. The lean default for an NQ/ES firm.
A26: CME data — non-pro DEPTH | B26: $18/exch/mo (4-for-3) | C26: $54 covers all 4 CME exchanges. Multiplied by Max Session Count — SET IT TO 1.
A27: CME data — PRO / Admin IDs | B27: $137.50/exch/mo | C27: Admins are always pro-rated. Each end user self-certifies pro/non-pro.
A28: ENTITLEMENT HYGIENE | B28: critical | C28: Inactive User IDs keep billing data fees until you disable entitlements. Automate deactivation — this is real money leakage.
A29: CME TPAP approval | B29: required pre-launch | C29: CME must approve the firm before live data go-live: legal name, org type/domicile, company-domain contact email, website, go-live date.
A30: -- ROUTING / EXECUTION (per account) --
A31: Rithmic — connection | B31: $25/mo per User ID | C31: Flat, any volume. +$0.10/contract routing. (AMP Futures / faq 2026)
A32: Rithmic — API add-on | B32: +$100/mo | C32: For automated/API accounts -> $125/mo total per ID. (AMP Futures 2026)
A33: Rithmic — data pass-through (Apex) | B33: $30-65/mo | C33: Apex passes the Rithmic data sub to traders on PA accounts. (damnpropfirms 2026)
A34: EdgeClear (Rithmic reseller) | B34: $20/mo + $0.10/ctr | C34: Among the lowest all-in Rithmic access. (edgeclear 2026)
A35: dxFeed | B35: ~$19/mo (retail) | C35: Budget feed; bundled with DXtrade; non-pro discounted. (propfirmapp, bulltraders 2026)
A36: CQG | B36: per-exchange fees | C36: Oldest feed (since 1980); per-individual exchange fees. (cqg.com 2026)
A37: -- FRONT-END PLATFORM (often free / firm-provided) --
A38: NinjaTrader / Tradovate | B38: $0-99/mo | C38: Free tiers common; $99/mo cuts commissions. Firm often covers. (damnpropfirms 2026)
A39: Quantower / R|Trader Pro | B39: ~$40 / free | C39: Quantower ~$40/mo; R|Trader Pro free. (damnpropfirms 2026)
A40: -- CME MARKET DATA (exchange; per account unless licensed) --
A41: CME data — NON-professional | B41: $15-25/exch/mo | C41: Per exchange bundle (Globex/CBOT/NYMEX/COMEX). (fortraders 2026)
...

Sheet Firm Economics
A1: Firm Economics — Live P&L (edit blue cells)
A2: Driven by rule design: set eval pass % and firm $/funded from the model tabs. Simulated futures firm, monthly basis.
A4: INPUTS / LEVERS | D4: BREAK-EVEN & PAYOUT RESERVE
A5: New challenge signups / month | B5: 500 | D5: Contribution per signup | E5: =B6*(1+B7+B8)*(1-B11-B14)-B9*B10-B13 -> 133.15
A6: Avg lifetime pre-funding revenue / signup ($) | B6: 475 | D6: Break-even signups / month | E6: =IF(E5<=0,"never (fix rules/pricing)",B12/E5) -> 90.12392
A7: Reset revenue uplift (% of base) | B7: 0.3
A8: Add-on / activation uplift (% of base) | B8: 0.2 | D8: Avg monthly payout obligation | E8: =B23 -> 107100
A9: Eval pass rate (from Eval Pass-Rate Model) | B9: 0.153 | D9: Reserve: 3x rule (min buffer) | E9: =B23*3 -> 321300
A10: Firm payout cost / funded trader ($, 50K) | B10: 1400
A11: Marketing + affiliate (% of gross) | B11: 0.4 | D11: Correlated-winner stress
A12: Fixed platform / data / staff ($/mo) | B12: 12000 | D12: Funded TRADERS at risk (distinct) | E12: 300
A13: Variable cost per signup ($) — from Platform & Data Costs | B13: ='Platform & Data Costs'!$B$57 -> 37.4 | D13: % hitting a big payout in same window | E13: 0.1
A14: Payment processing (% of gross) | B14: 0.06 | D14: Big payout size ($) | E14: 3000
A15: Max concurrent funded accts / trader | B15: 5 | D15: Correlated-winner cash spike | E15: =E12*E13*E14*B15 -> 450000
A17: MONTHLY P&L | D17: RESERVE TO HOLD (max of the two) | E17: =MAX(E9,E15) -> 450000
A18: Base fee revenue | B18: =B5*B6 -> 237500
A19: Reset revenue | B19: =B18*B7 -> 71250
A20: Add-on / activation revenue | B20: =B18*B8 -> 47500
A21: GROSS REVENUE | B21: =B18+B19+B20 -> 356250
A22: Funded traders / month | B22: =B5*B9 -> 76.5
A23: Payout cost (funded x firm $/funded) | B23: =B22*B10 -> 107100
A24: Marketing + affiliate | B24: =B21*B11 -> 142500
A25: Payment processing | B25: =B21*B14 -> 21375
A26: Variable cost | B26: =B5*B13 -> 18700
A27: Fixed platform / data / staff | B27: =B12 -> 12000
A28: TOTAL COSTS | B28: =B23+B24+B25+B26+B27 -> 301675
A29: NET PROFIT (monthly) | B29: =B21-B28 -> 54575
A30: Net margin | B30: =IF(B21=0,0,B29/B21) -> 0.15319298
A31: NET PROFIT (annualised) | B31: =B29*12 -> 654900

Sheet Cost Stack
A1: Cost Stack — The Full Picture (what we were missing)
A2: Every real operating cost, not just payouts + marketing. Blue = editable. Reveals how thin the true margin is and where it goes.
A4: COST INPUTS (blue = edit) | D4: WHERE THE MONEY GOES (% of gross)
A5: Paid marketing (% of gross) | B5: 0.1 | D5: Trader payouts | E5: =IF(B17=0,0,B18/B17) -> 0.30063158
A6: Affiliate commissions (% of gross) | B6: 0.15 | D6: Paid marketing | E6: =IF(B17=0,0,B19/B17) -> 0.1
A7: Refunds & chargebacks (% of gross) | B7: 0.05 | D7: Affiliate | E7: =IF(B17=0,0,B20/B17) -> 0.15
A8: Inbound payment processing (% of gross) | B8: 0.06 | D8: Refunds & chargebacks | E8: =IF(B17=0,0,B21/B17) -> 0.05
A9: Payout processing fee (% of payouts) | B9: 0.02 | D9: Payment processing | E9: =IF(B17=0,0,B22/B17) -> 0.06
A10: CME data + platform / funded acct / mo — from Platform & Data Costs | B10: ='Platform & Data Costs'!$B$55 -> 22 | D10: Payout processing | E10: =IF(B17=0,0,B23/B17) -> 0.0060126316
A11: Trading infra / tech / dev ($/mo, excl. platform licence) | B11: 8000 | D11: CME data + platform | E11: =IF(B17=0,0,B24/B17) -> 0.0047242105
A12: Support & risk staff ($/mo) | B12: 18000 | D12: Infra / tech | E12: =IF(B17=0,0,B25/B17) -> 0.036491228
A13: Compliance & legal ($/mo) | B13: 6000 | D13: Support & risk | E13: =IF(B17=0,0,B26/B17) -> 0.050526316
A14: Fraud / abuse loss (% of gross) | B14: 0.02 | D14: Compliance & legal | E14: =IF(B17=0,0,B27/B17) -> 0.016842105
D15: Fraud / abuse | E15: =IF(B17=0,0,B28/B17) -> 0.02
A16: MONTHLY COST BREAKDOWN | D16: NET MARGIN | E16: =B31 -> 0.20477193
A17: Gross revenue (from Economics) | B17: ='Firm Economics'!$B$21 -> 356250
A18: Trader payouts (from Economics) | B18: ='Firm Economics'!$B$23 -> 107100 | D18: Marketing + affiliate is the largest line (35-45% of gross). Payouts are the second. Everything else is the "hidden stack".
A19: Paid marketing | B19: ='Firm Economics'!$B$21*B5 -> 35625 | D19: This is why margins are thin and volume is everything — and why a payout spike or a CAC increase can flip the firm to a loss.
A20: Affiliate commissions | B20: ='Firm Economics'!$B$21*B6 -> 53437.5
A21: Refunds & chargebacks | B21: ='Firm Economics'!$B$21*B7 -> 17812.5
A22: Inbound payment processing | B22: ='Firm Economics'!$B$21*B8 -> 21375
A23: Payout processing fee | B23: ='Firm Economics'!$B$23*B9 -> 2142
A24: CME data + platform (funded x rate) | B24: ='Firm Economics'!$B$22*B10 -> 1683
A25: Trading infra / tech / dev + platform licence | B25: =B11+'Platform & Data Costs'!$B$48 -> 13000
A26: Support & risk staff | B26: =B12 -> 18000
A27: Compliance & legal | B27: =B13 -> 6000
A28: Fraud / abuse loss | B28: ='Firm Economics'!$B$21*B14 -> 7125
A29: TOTAL COSTS (incl. payouts) | B29: =SUM(B18:B28) -> 283300
A30: NET PROFIT (monthly) | B30: =B17-B29 -> 72950
A31: Net margin | B31: =IF(B17=0,0,B30/B17) -> 0.20477193
A32: NET PROFIT (annualised) | B32: =B30*12 -> 875400

Sheet Pricing Power
A1: Pricing Power — How Low Can You Price?
A2: Per-signup unit economics vs list price and discount depth. Finds the discount floor where a signup stops paying for itself.
A4: INPUTS / LEVERS
A5: List price — 50K eval ($) | B5: 165
A6: Lifetime purchase multiple / signup | B6: 2.9
A7: Activation fee on pass — NOT discounted ($) | B7: 90
A8: Customer acquisition cost / signup ($) | B8: 80
A9: Cost to serve / signup ($) | B9: 34
A10: Eval pass rate (from Economics) | B10: ='Firm Economics'!$B$9 -> 0.153
A11: Firm payout cost / funded (from Economics) | B11: ='Firm Economics'!$B$10 -> 1400
A13: PRICE FLOOR (per-signup break-even)
A14: Payout liability / signup (pass x firm$/funded) | B14: =B10*B11 -> 214.2
A15: Activation revenue / signup (pass x fee) | B15: =B10*B7 -> 13.77
A16: Min effective price to break even ($) | B16: =MAX(0,(B8+B9+B14-B15)/B6) -> 108.42414
A17: Max discount off list before losing money | B17: =IF(B5=0,0,MAX(0,1-B16/B5)) -> 0.34288401
A19: DISCOUNT SENSITIVITY (per signup)
A20: Discount off list | B20: Effective price | C20: Revenue/signup | D20: Contribution/signup | E20: Contribution margin
A21: 0 | B21: =B5*(1-A21) -> 165 | C21: =B21*B6+B15 -> 492.27 | D21: =C21-B8-B9-B14 -> 164.07 | E21: =IF(C21=0,0,D21/C21) -> 0.33329271
A22: 0.2 | B22: =B5*(1-A22) -> 132 | C22: =B22*B6+B15 -> 396.57 | D22: =C22-B8-B9-B14 -> 68.37 | E22: =IF(C22=0,0,D22/C22) -> 0.17240336
A23: 0.4 | B23: =B5*(1-A23) -> 99 | C23: =B23*B6+B15 -> 300.87 | D23: =C23-B8-B9-B14 -> -27.33 | E23: =IF(C23=0,0,D23/C23) -> -0.090836574
A24: 0.6 | B24: =B5*(1-A24) -> 66 | C24: =B24*B6+B15 -> 205.17 | D24: =C24-B8-B9-B14 -> -123.03 | E24: =IF(C24=0,0,D24/C24) -> -0.59964907
A25: 0.8 | B25: =B5*(1-A25) -> 33 | C25: =B25*B6+B15 -> 109.47 | D25: =C25-B8-B9-B14 -> -218.73 | E25: =IF(C25=0,0,D25/C25) -> -1.9980817
A26: 0.9 | B26: =B5*(1-A26) -> 16.5 | C26: =B26*B6+B15 -> 61.62 | D26: =C26-B8-B9-B14 -> -266.58 | E26: =IF(C26=0,0,D26/C26) -> -4.3261928
A28: Revenue/signup = effective price x lifetime multiple + expected activation revenue. Costs = CAC + cost to serve + expected payout liability.
A29: The floor is where contribution hits zero. The three ways to discount deeper without losing money:
A30: 1) Raise the lifetime multiple — short eval windows + resets + many accounts mean each signup rebuys often (Apex 30-day expiry is a rebuy engine).
A31: 2) Keep a non-discounted activation fee — pure margin on every funded trader that promo codes cannot touch.
A32: 3) Lower firm$/funded via tighter funded rules (caps/consistency) — cuts the fixed payout liability that deep discounts cannot cover.
A33: Payout liability per signup is INDEPENDENT of entry price, so entry alone cannot fund it at deep discounts — that is the core constraint.

Sheet Risk Engine (VaR)
A1: Portfolio Risk Engine — Correlated Payout VaR & Ruin Probability
A2: The firm is an insurance book: N funded traders with CORRELATED outcomes (copy trading, one-directional NQ days, news). Gaussian-copula Monte Carlo. Edit inputs in mc_lifecycle.py portfolio_risk() and re-run.
A4: INPUTS (baseline Merit scale)
A5: Signups / month | B5: 500
A6: Blended eval pass | B6: 0.16
A7: Avg funded life (months) | B7: 2.2
A8: Active funded stock | B8: 176
A9: P(payout | funded-month) | B9: 0.3
A10: Payout size mu/sd/cap ($) | B10: 850 / 700 / 1500
A11: Cash per signup ($, haircut) | B11: 220
A12: Fixed opex / month ($) | B12: 33000
A14: MONTHLY PAYOUT DISTRIBUTION BY CORRELATION (20,000 sims)
A15: Trader correlation rho | B15: Mean / mo | C15: St. dev | D15: VaR 95 | E15: VaR 99 | F15: CVaR 99 (tail avg) | G15: CVaR99 / mean
A16: rho = 0.05 | B16: 45307.296 | C16: 13266.906 | D16: 68526.194 | E16: 79604.29 | F16: 84838.996 | G16: 1.8725239
A17: rho = 0.15 | B17: 45236.543 | C17: 21361.623 | D17: 84384.434 | E17: 102402.77 | F17: 109591.29 | G17: 2.4226274
A18: rho = 0.3 | B18: 45379.934 | C18: 30044.573 | D18: 103251.98 | E18: 125068.35 | F18: 132896.71 | G18: 2.9285348
A20: 18-MONTH RUIN PROBABILITY (rho=0.30, 8,000 paths) — by starting capital & regime
A21: Scenario | B21: $150k | C21: $250k | D21: $350k | E21: $500k | F21: $750k | G21: What it models
A22: base | B22: 0.000375 | C22: 0 | D22: 0 | E22: 0 | F22: 0 | G22: Normal operations, correlated months only
A23: rev_shock | B23: 0.007125 | C23: 0.00075 | D23: 0.00025 | E23: 0 | F23: 0 | G23: Fees -40% for months 7-12 (PSP freeze / sales slump)
A24: juice_wave | B24: 0.002 | C24: 0.000125 | D24: 0 | E24: 0 | F24: 0 | G24: Coordinated extraction: payout prob x1.5, severity x1.2, months 5-7
A25: combined | B25: 0.06275 | C25: 0.016375 | D25: 0.003625 | E25: 0.000125 | F25: 0 | G25: Both at once — the FTT/Thrive death pattern
A27: SELECTION MATH — WHY THE BUSINESS WORKS (evals select noise, not skill)
A28: The base rate (literature) | B28: Chague/De-Losso/Giovannetti (N=19,646, Brazilian futures): 97% of PERSISTENT day traders lose net of fees; no learning effect (experience coefficient NEGATIVE). Taiwan 15-yr (Barber-Odean): <1% persistently profitable. Durable edge in the population: ~1-3%.
A29: An eval is a weak classifier | B29: A Sharpe-1.0 trader separates from a Sharpe-0 trader by only d-prime = (1/sqrt(252)) x sqrt(10) = 0.20 sigma over a 10-day eval -> classifier AUC = 55.6%. Barely better than a coin flip. Pass rate is a PRICE knob, not a QUALITY filter.
A30: Bayes: who is actually funded | B30: P(skilled)=2%, P(pass|skilled)=50%, P(pass|unskilled)=14% -> blended pass 14.7% and P(skilled|FUNDED) = 6.8%. ~93% of your funded book has zero-or-negative true edge and will revert; the liability tail = the true 7% plus lucky streaks of the 93%.
A31: Design implications | B31: (1) Funded time-gates (win days, cadence, consistency) work because they let the 93% revert BEFORE cash leaves. (2) Live conversion exists to remove the true 7% from the sim book. (3) Rebuy revenue is durable because there is NO learning effect — failed traders do not come back stronger. All three pillars are now derived, not assumed.
A32: Day-one rho estimator | B32: Estimate trader correlation empirically from daily data: rho-hat = (Var over days of daily %-profitable minus pbar(1-pbar)/n) / (pbar(1-pbar)). Beta-binomial overdispersion — one spreadsheet column once live.
A33: t-copula tail stress | B33: Gaussian copulas have ZERO tail dependence (the 2008 error). A t-copula (nu=4) at rho=0.15 lifts CVaR99 by ~5% ($110k -> $115k). Our conservative rho=0.30 Gaussian already dominates it — reserve rule stands.
A35: THE TAIL IS ALL CORRELATION: mean payouts (~$45k/mo) barely move with rho, but the 1-in-100 month nearly doubles ($79k at rho=0.05 -> $125k at rho=0.30). Copy trading, stacked accounts, and one-directional NQ days ARE the risk — not average winner volume.
A36: RESERVE RULE (replaces "3x average"): hold >= CVaR99 of monthly payouts, i.e. ~2.9x mean monthly payouts at rho=0.30. At baseline scale that is ~$135k of payout reserve, ring-fenced from opex.
A37: RUIN COMES FROM REGIMES, NOT MONTHS: no single bad month kills a funded book with positive drift. Death = a persistent regime (revenue shock + extraction wave together). $350k starting capital holds combined-stress ruin to ~0.2%; $150k runs 6%. The insider "$300-500k reserves" benchmark is DERIVED here from first principles.
A38: Scale note: funded stock and fees both grow 8%/mo in the paths; reserves must grow with the book. Re-run portfolio_risk() whenever plan caps, pass rates, or scale change.

Sheet Risk Operations
A1: Risk Operations — Dashboard, Abuse Detection, Monitoring Statistics
A2: The operating layer that keeps the math true. FTT died blind; this is the sight system. No-denial brand = abuse is caught at DETECTION time, never at payout time.
A4: DAILY LIABILITY DASHBOARD (the FTT lesson — always visible)
A5: Metric | B5: Formula | C5: Threshold / response
A6: Open Liability | B6: SUM(withdrawable balance) across ALL funded accounts, real time | C6: The number FTT never had. Red if > payout reserve.
A7: Eligible-Next-7-Days | B7: SUM(withdrawable) over accounts clearing gates (win days, buffer, gap) within 7d | C7: Forecasts the request wave before it arrives.
A8: Reserve Coverage Ratio | B8: Payout reserve / CVaR99(monthly payouts) from Risk Engine | C8: >= 1.0 required; < 1.0 pauses marketing spend, not payouts.
A9: Plan Loss Ratio (30d) | B9: Payouts paid / fees collected, per plan, trailing 30 days | C9: Circuit breaker: > 60% pauses NEW SALES of that plan (never touches existing traders).
A10: Payout Velocity | B10: $ requested per day vs 30-day average | C10: Spike > 2.5x average = same-day investigation for coordination.
A11: Pass-Rate CUSUM | B11: S_t = max(0, S_(t-1) + (daily pass% - baseline - k)); k = 0.5 sigma | C11: Alarm at h = 4-5 sigma: a plan is being systematically beaten -> inspect before the funded wave hits.
A13: ABUSE TAXONOMY & DETECTION SIGNALS (2026 vendor-grade practice)
A14: Scheme | B14: Signature | C14: Detection method
A15: No-risk hedge (the #1 signature) | B15: Account A profits ONLY when paired account B loses; long/short same size, same time, across accounts or sibling firms | C15: Correlation engine on position vectors; inverse P&L correlation < -0.8 between linked entities = ring
A16: Copy-trading ring | B16: Groups buy evals together, rotate who reaches payout; same-second fills, identical sequences across "unrelated" accounts | C16: Graph clustering on order timestamps + entity resolution (email/device/IP/payment); catches networks, not accounts
A17: Account fleet / multi-identity | B17: One person, 20-30 accounts under different names to beat max-account caps | C17: KYC + device fingerprint + behavioral biometrics; entity resolution BEFORE funding, not after
A18: News straddle | B18: Bracket orders seconds before Tier-1 releases (CPI/FOMC/NFP) exploiting sim fills | C18: Flag entries within +-N sec of calendar events; strategy-level (repeated), not single trades
A19: Latency / stale-quote arb | B19: Exploiting sim feed delay vs real market; toxic flow profile | C19: Fill-price vs NBBO deviation distribution; sub-second round trips at abnormal win rates
A20: Martingale eval-gaming | B20: Doubling size after losses to brute-force the eval (survivors become funded liabilities) | C20: Size-after-loss regression; strategy-level threshold (e.g. >30% of sequence), context-aware to avoid false positives
A22: OPERATING PRINCIPLES
A23: Principle | B23: Practice | C23: Why
A24: Instant auto-approval + no denials | B24: Eligibility computed mechanically by the rules engine -> approval is INSTANT and automatic; settlement 2-3 business days via Rise. Abuse handled at DETECTION time (warning/restriction/closure per ToS), never at request time. Caps bound the worst case of any auto-approved cycle. | C24: Every enforcement documented: trades, timestamps, rule version, approver. Evidence-grade or it did not happen.
A25: Two risk-event classes | B25: Mechanical breaches (drawdown/DLL) auto-enforce instantly; behavioral flags route to human review | C25: Never auto-punish behavior; blunt rules punish good traders and torch reviewer trust.
A26: Entitlement hygiene | B26: Auto-disable Rithmic User IDs + data entitlements on churn | C26: Direct cost control: inactive IDs bill until disabled (actual Rithmic quote).
A27: Weekly risk ritual | B27: Review: loss ratios by plan, CUSUM charts, top-20 open liabilities, flagged networks, reserve coverage | C27: Output = decisions: plan price/rule tweaks, sales pauses, graduations to live.
A28: Tooling | B28: Graph-based detection is a product category now: QuantSentry, propGuard, Axcera RiskGuard, Centroid PropShield; FPFX/platform native tools | C28: Buy detection, own the DECISION layer. Budget it in Cost Stack from day 1.
A30: RING RESISTANCE — hedged-pair economics vs ruleset (50K, the "existential threat" priced)
A31: Plan | B31: Hedged-pair economics | C31: Verdict
A32: MFF Rapid EOD | B32: Pair cost $252 | ~7 days | take: UNCAPPED daily above $2,100 buffer | ring ~$270+/day, repeatable DAILY | C32: MAGNET — no funded consistency + no cap + daily cadence is exactly what rings hunt. Their 3-acct cap is the only brake.
A33: TPT PRO | B33: Pair cost $204 | ~6 days | take: uncapped above buffer, 50% penalty below | C33: EXPOSED — penalty route still yields fast extraction; daily cadence.
A34: Apex EOD | B34: Pair cost $238 | ~8 days | take $1,500 (100% split) but 50% funded consistency forces multi-day spread | C34: MODERATE — cap + consistency bound the prize and force time.
A35: MERIT Core EOD | B35: Pair cost $158 | ~7 days | take capped $1,350 (90%), then 5-day gap; 30% consistency + 5 win days at $150+ mean the market must cooperate MULTIPLE days — the hedge is no longer riskless | C35: RESISTANT — ring $/day ceiling ~$190, per-trader lifetime capped by 8-payout live ladder.
A36: MERIT Rapid Daily | B36: Pair cost $176 | daily cadence BUT $1,000 cap + 40% consistency | C36: RESISTANT — daily magnet marketing with a bounded daily prize.
A37: The defense stack | B37: Rules set the PRIZE CEILING (caps, consistency, gaps, ladders); detection (entity resolution, inverse-P&L correlation, graph clustering) sets the CATCH RATE | C37: You need both: rules make rings unprofitable-per-day; detection makes them terminal. Neither alone suffices.
A39: Sources: Axcera (coordinated hedging ring described by a firm CEO as "existential threat"), QuantSentry/propGuard (graph-based network detection), fxproptech risk-engine spec (strategy-level vs isolated events), Rithmic quote (entitlement billing), FTT post-mortem (insider log).

Sheet Live Program
A1: SIM -> Live Conversion — How Firms Do It (2026)
A2: Live = real capital via an NFA-registered broker. It is a gated graduation used as a retention carrot AND a risk funnel. Reference + our design.
A4: HOW THE MAJORS RUN IT
A5: Firm | B5: Trigger to go live | C5: Mechanics
A6: Apex | B6: Invitation-only (discretionary) | C6: Separate live dept. Judges discipline, consistency, lifetime SIM payouts, speed. Drops to 1 live acct (max 5 by regulation vs 20 SIM), unlocks +1 per $4,500 live profit. SIM profit -> Bonus Vault (20-40% bonus). 100% split, daily payouts, no consistency on live.
A7: Phidias (Express to Live) | B7: On FIRST payout | C7: Converts to real LIVE account with Dorman Trading (NFA broker). No per-payout cap, no 6-payout ceiling. 80/20 split, static drawdown, no consistency gate.
A8: Take Profit Trader | B8: Test -> PRO (sim) -> PRO+ (live) | C8: PRO+ is live on Tradovate execution, 90/10, EOD drawdown (vs PRO intraday). The intraday-DD PRO phase is where most accounts die ("easy to pass, hard to keep").
A9: Lucid (Live / LucidMaxx) | B9: Milestone; restructured Feb 2026 | C9: $0 starting balance + EOD drawdown live model. One-time bonus = live target (doubles initial live capital at first target). Faster SIM->Live transition.
A10: MyFundedFutures | B10: 30 winning days of consistency | C10: Moves proven traders to a live funded account after sustained consistency.
A11: Topstep | B11: Risk team clears you (no fixed timeframe) | C11: Express Funded (sim) -> Live Funded Account when risk team judges readiness. Varies by trader.
A13: WHY LIVE EXISTS — IT IS A COST REDUCER (pure B-book firm)
A14: THE CORE ECONOMICS: every SIM payout is a direct treasury loss. A consistently profitable trader on SIM is an open-ended drain — they keep winning, you keep paying. Moving them to a REAL live account converts that drain into real market P&L: their payouts are funded by actual gains, and your exposure collapses to the ONE-TIME allocated drawdown/initial balance.
A15: THEREFORE LIVE CAN BE UNRESTRICTED: daily payouts, no consistency, no caps, no winning-day gates — none of it costs you anything on live, because the market (not your treasury) pays the winner. Restrictions only protect you in SIM. This is exactly why Apex/MFF/Lucid live terms are BETTER than their sim terms (100% split, daily, no rules).
A16: THE GATE IS THE PRODUCT: graduate only proven winners (e.g. N payouts, $X lifetime SIM profit, or risk-team review). Each graduation caps that traders remaining lifetime cost at the allocated drawdown — the sim already models this via max_payouts (Apexs 6-payout ladder IS a live-conversion trigger).
A17: REAL COSTS OF LIVE (small but non-zero): margin capital posted at the FCM, clearing/commissions, and the regulatory perimeter (real execution = IB/FCM territory — see Legal & Compliance). Launch SIM-only; add the live tier once volume justifies the FCM relationship.
